Workbook

Sheet PAY
A1: OFFICE Of HIGH SCHOOL BALIPUR
A2: INCOME TAX CALCULATION (GA-55) 2020-21
A3: NAME : | B3: Laxman Devda | J3: PAN : | L3: KLP00232K
A4: Desig : | B4: Madhymik Shikshak | J4: AADHAR : | L4: 12345678911123
A5: Account: | B5: 57993363020 | J5: IFSC: | L5: SBIN0030142
A6: Month | B6: Pay | C6: Grad Pay | D6: D.A. | E6: H.R. | F6: Con.Allo./ Disability All. | G6: Oth.Allo. | H6: Total | I6: Relief fund/Recovery | J6: G.P.F/ NPS | K6: G.I.S | L6: Net | M6: Pro. Tax | N6: Income Tax | O6: Net Amount | P6: Bill No. & T.V. No.
A7: 43891 | B7: 48692 | C7: 0 | D7: 5000 | E7: 0 | F7: 0 | G7: 0 | H7: =G7+F7+E7+D7+C7+B7 -> 53692 | I7: 0 | J7: 5369 | K7: 200 | L7: =H7-(I7+J7+K7) -> 48123 | M7: 208 | N7: 1000 | O7: =L7-(M7+N7) -> 46915
A8: 43922 | B8: 48692 | C8: 0 | D8: 5000 | E8: 0 | F8: 0 | G8: 0 | H8: =G8+F8+E8+D8+C8+B8 -> 53692 | I8: 0 | J8: 5369 | K8: 200 | L8: =H8-(I8+J8+K8) -> 48123 | M8: 208 | N8: 1000 | O8: =L8-(M8+N8) -> 46915
A9: 43952 | B9: 48692 | C9: 0 | D9: 5000 | E9: 0 | F9: 0 | G9: 0 | H9: =G9+F9+E9+D9+C9+B9 -> 53692 | I9: 0 | J9: 5369 | K9: 200 | L9: =H9-(I9+J9+K9) -> 48123 | M9: 208 | N9: 1000 | O9: =L9-(M9+N9) -> 46915
A10: 43983 | B10: 48692 | C10: 0 | D10: 5000 | E10: 0 | F10: 0 | G10: 0 | H10: =G10+F10+E10+D10+C10+B10 -> 53692 | I10: 0 | J10: 5369 | K10: 200 | L10: =H10-(I10+J10+K10) -> 48123 | M10: 208 | N10: 1000 | O10: =L10-(M10+N10) -> 46915
A11: 44013 | B11: 48692 | C11: 0 | D11: 5000 | E11: 0 | F11: 0 | G11: 0 | H11: =G11+F11+E11+D11+C11+B11 -> 53692 | I11: 0 | J11: 5369 | K11: 200 | L11: =H11-(I11+J11+K11) -> 48123 | M11: 208 | N11: 1000 | O11: =L11-(M11+N11) -> 46915
A12: 44044 | B12: 48692 | C12: 0 | D12: 5000 | E12: 0 | F12: 0 | G12: 0 | H12: =G12+F12+E12+D12+C12+B12 -> 53692 | I12: 0 | J12: 5369 | K12: 200 | L12: =H12-(I12+J12+K12) -> 48123 | M12: 208 | N12: 1000 | O12: =L12-(M12+N12) -> 46915
A13: 44075 | B13: 48692 | C13: 0 | D13: 5000 | E13: 0 | F13: 0 | G13: 0 | H13: =G13+F13+E13+D13+C13+B13 -> 53692 | I13: 0 | J13: 5369 | K13: 200 | L13: =H13-(I13+J13+K13) -> 48123 | M13: 208 | N13: 1000 | O13: =L13-(M13+N13) -> 46915
A14: 44105 | B14: 48692 | C14: 0 | D14: 5000 | E14: 0 | F14: 0 | G14: 0 | H14: =G14+F14+E14+D14+C14+B14 -> 53692 | I14: 0 | J14: 5369 | K14: 200 | L14: =H14-(I14+J14+K14) -> 48123 | M14: 208 | N14: 1000 | O14: =L14-(M14+N14) -> 46915
A15: 44136 | B15: 48692 | C15: 0 | D15: 5000 | E15: 0 | F15: 0 | G15: 0 | H15: =G15+F15+E15+D15+C15+B15 -> 53692 | I15: 0 | J15: 5369 | K15: 200 | L15: =H15-(I15+J15+K15) -> 48123 | M15: 208 | N15: 1000 | O15: =L15-(M15+N15) -> 46915
A16: 44166 | B16: 48692 | C16: 0 | D16: 5000 | E16: 0 | F16: 0 | G16: 0 | H16: =G16+F16+E16+D16+C16+B16 -> 53692 | I16: 0 | J16: 5369 | K16: 200 | L16: =H16-(I16+J16+K16) -> 48123 | M16: 208 | N16: 1000 | O16: =L16-(M16+N16) -> 46915
A17: 44197 | B17: 48692 | C17: 0 | D17: 5000 | E17: 0 | F17: 0 | G17: 0 | H17: =G17+F17+E17+D17+C17+B17 -> 53692 | I17: 0 | J17: 5369 | K17: 200 | L17: =H17-(I17+J17+K17) -> 48123 | M17: 208 | N17: 1000 | O17: =L17-(M17+N17) -> 46915
A18: 44228 | B18: 48692 | C18: 0 | D18: 5000 | E18: 0 | F18: 0 | G18: 0 | H18: =G18+F18+E18+D18+C18+B18 -> 53692 | I18: 0 | J18: 5369 | K18: 200 | L18: =H18-(I18+J18+K18) -> 48123 | M18: 212 | N18: 2000 | O18: =L18-(M18+N18) -> 45911
A19: DA Arrear | B19: 0 | C19: 0 | D19: 0 | E19: 0 | F19: 0 | G19: 0 | H19: =G19+F19+E19+D19+C19+B19 -> 0 | I19: 0 | J19: 0 | K19: 0 | L19: =H19-(I19+J19+K19) -> 0 | M19: 0 | N19: 0 | O19: =L19-(M19+N19) -> 0
A20: Salary Arrear 1 | B20: 0 | C20: 0 | D20: 0 | E20: 0 | F20: 0 | G20: 0 | H20: =G20+F20+E20+D20+C20+B20 -> 0 | I20: 0 | J20: 0 | K20: 0 | L20: =H20-(I20+J20+K20) -> 0 | M20: 0 | N20: 0 | O20: =L20-(M20+N20) -> 0
A21: Salary Arrear 2 | B21: 0 | C21: 0 | D21: 0 | E21: 0 | F21: 0 | G21: 0 | H21: =G21+F21+E21+D21+C21+B21 -> 0 | I21: 0 | J21: 0 | K21: 0 | L21: =H21-(I21+J21+K21) -> 0 | M21: 0 | N21: 0 | O21: =L21-(M21+N21) -> 0
A22: Salary Arrear 3 | B22: 0 | C22: 0 | D22: 0 | E22: 0 | F22: 0 | G22: 0 | H22: =G22+F22+E22+D22+C22+B22 -> 0 | I22: 0 | J22: 0 | K22: 0 | L22: =H22-(I22+J22+K22) -> 0 | M22: 0 | N22: 0 | O22: =L22-(M22+N22) -> 0
A23: Other | B23: 0 | C23: 0 | D23: 0 | E23: 0 | F23: 0 | G23: 0 | H23: =G23+F23+E23+D23+C23+B23 -> 0 | I23: 0 | J23: 0 | K23: 0 | L23: =H23-(I23+J23+K23) -> 0 | M23: 0 | N23: 0 | O23: =L23-(M23+N23) -> 0
A24: TOTAL | B24: =B23+B22+B21+B20+B19+B18+B17+B16+B15+B14+B13+B12+B11+B10+B9+B8+B7 -> 584304 | C24: =C23+C22+C21+C20+C19+C18+C17+C16+C15+C14+C13+C12+C11+C10+C9+C8+C7 -> 0 | D24: =D23+D22+D21+D20+D19+D18+D17+D16+D15+D14+D13+D12+D11+D10+D9+D8+D7 -> 60000 | E24: =E23+E22+E21+E20+E19+E18+E17+E16+E15+E14+E13+E12+E11+E10+E9+E8+E7 -> 0 | F24: =F23+F22+F21+F20+F19+F18+F17+F16+F15+F14+F13+F12+F11+F10+F9+F8+F7 -> 0 | G24: =G23+G22+G21+G20+G19+G18+G17+G16+G15+G14+G13+G12+G11+G10+G9+G8+G7 -> 0 | H24: =H23+H22+H21+H20+H19+H18+H17+H16+H15+H14+H13+H12+H11+H10+H9+H8+H7 -> 644304 | I24: =I23+I22+I21+I20+I19+I18+I17+I16+I15+I14+I13+I12+I11+I10+I9+I8+I7 -> 0 | ... K24: =K23+K22+K21+K20+K19+K18+K17+K16+K15+K14+K13+K12+K11+K10+K9+K8+K7 -> 2400 | L24: =H24-(I24+J24+K24) -> 577476 | M24: =M23+M22+M21+M20+M19+M18+M17+M16+M15+M14+M13+M12+M11+M10+M9+M8+M7 -> 2500 | N24: =N23+N22+N21+N20+N19+N18+N17+N16+N15+N14+N13+N12+N11+N10+N9+N8+N7 -> 13000 | O24: =O23+O22+O21+O20+O19+O18+O17+O16+O15+O14+O13+O12+O11+O10+O9+O8+O7 -> 561976
B26: =B3 -> Laxman Devda
B27: =B4 -> Madhymik Shikshak
A29: ट्रायबल विभाग के शिक्षकों का संगठन " ट्रायबल वेल्फेयर टीचर्स एसोसिएशन " मध्य प्रदेश के सभी शिक्षकों के सहयोग के लिए निर्मित हमारी वेब साइट www.twtamp.in का अवलोकन अवश्य करें
A31: प्रदेशाध्यक्ष श्री डी के सिंगौर के मार्गदर्शन में श्री विजय उपाध्याय के सहयोग से प्रदेश महासचिव सुरेश यादव (9926809650) द्वारा निर्मित

Sheet DEDUCTION
A1: वेतन के अतिरिक्त कटौतियाँ ,आय / जमा राशी एवं छूट का विवरण
A2: =PAY!A1 -> OFFICE Of HIGH SCHOOL BALIPUR
A3: =PAY!B3 -> Laxman Devda | C3: =PAY!B4 -> Madhymik Shikshak | E3: =PAY!L3 -> KLP00232K
A4: 1 मकान किराया भत्ता (जो छूट प्राप्त करना है ) | B4: 0 | C4: 20 धारा 80 TTA बचत खाते का ब्याज 10000/- तक कर मुक्त उसके बाद कर योग्य 80TTB वरिष्ठ नागरिको के लिए 50000/- उसके बाद कर योग्य t (80 TTA/80 TTB) | D4: 0 | E4: BASIC + D.A.
A5: 2 मनोरंजन भत्ता धारा 16(ii) अंतर्गत | B5: 0 | C5: 21 अन्य आय (FD पर ब्याज ,अन्य ब्याज या अन्य स्त्रोत से आय ) | D5: 0 | E5: =PAY!B24+PAY!C24+PAY!D24 -> 644304
A6: 3 व्यवसाय /वृत्ती कर धारा 16 (iii) अंतर्गत | B6: =PAY!M24 -> 2500 | C6: 22 अन्य जमा राशि (80C अंतर्गत) | D6: 0 | E6: Taxable Amt
A7: 4 गृह संपत्ति से आय - किराया | B7: 0 | C7: 23 घटाइये-धारा 80CCD (2) नियोक्ता द्वारा पेंशन अंशदान की राशि (अधिकतम वेतन का 10% ) पृथक से छूट | D7: 0 | E7: ='OLD TAX PLAN '!O47 -> 500980
A8: 5 गृहकर | B8: 0 | C8: 24 धारा 80 CCD 1 (B) वेतन एवं नियोक्ता के अंशदान के अतिरिक्त 50000 तक का निवेश | D8: 0 | E8: Tax Deposited
A9: 6 गृह ऋण का -मूल (जो वेतन से नहीं काटा गया) | B9: 0 | C9: 25 धारा 80 D मेडिक्लेम पालिसी (स्वय,जीवन साथी,बच्चों की 25000/-) आश्रित मातापिता का मेडिक्लेम 50000/- | D9: 0 | E9: =PAY!N24 -> 13000
A10: 7 गृह ऋण का -ब्याज (जो वेतन से नहीं काटा गया) | B10: 0 | C10: 26 धारा 80 DD दिव्यांग आश्रित के इलाज का खर्च का खर्च 40% से 79 % तक दिव्यांग 75000/- 80% से अधिक दिव्यांग 125000/- | D10: 0 | E10: Rebate Under Section 80C, 80CCC, 80CCD(1)
A11: 8 जीवन बीमा प्रीमियम (एलआईसी) | B11: 0 | C11: 27 धारा 80DDB वीनिर्दिष्ट बीमारियों मे स्वयं या आश्रीत का इलाज का खर्च 40000/-, 60 से अधिक आयु वर्ग के लिए 100000/- | D11: 0
A12: 9 पी.एल.आई. (PLI) | B12: 0 | C12: 28 धारा 80 E उच्च शिक्षा ऋण के ब्याज को 8 वर्ष तक मुक्त किया गया है | D12: 0
A13: 10 शिक्षण शुल्क l (Tution Fees) | B13: 0 | C13: 29 धारा 80 G राष्ट्रिय,धर्मिक ,परमार्थ एवं सामाजिक कार्य हेतु दान राशी 50% से 100% कर मुक्त (आयकर विभाग की सूची अनुसार) | D13: 0 | E13: ='OLD TAX PLAN '!O30 -> 90828
A14: 11 ULIP/वार्षिक प्लान | B14: 0 | C14: 30 धारा 80 U दिव्यांग व्यक्ति को छुट 75000/- 80 प्रतिशत दिव्यांग 125000/- | D14: 0 | E14: अन्य कटौतियाँ 80C, 80CCC, 80CCD(1) के अतिरिक्त
A15: 12 राष्ट्रीय बचत पत्र (NSC) | B15: 24000 | C15: 31 धारा 80 GGA वैज्ञानिक ,सामाजिक एवं ग्रामीण विकास हेतु दिया गया दान | D15: 0
A16: 13 राष्ट्रीय बचत पत्र पर प्राप्त ब्याज | B16: 0 | C16: 32 म्यूचुअल फंड / ELSS प्लान | D16: 0
A17: 14 लोक भविष्य निधी (PPF) | B17: 0 | C17: 33 स्थगित वार्षिकी (Defferred Annuty) | D17: 0
A18: 15 राष्ट्रीय बचत योजना (NSS) | B18: 0 | C18: 34 धारा 89 के तहत राहत | D18: 0 | E18: ='OLD TAX PLAN '!O44 -> 0
A19: 16 सुकन्या समृद्धि योजना मे जमा (SSY) | B19: 0 | C19: 35 वेतन के अलावा जमा किया गया आयकर (TDS) | D19: 0
A20: 17 सामान्य भविष्य निधि (GPF) | B20: 0 | C20: 36 सरकारी पेंशन योजना मे अंशदान ECPF | D20: 0 | E20: Income Tax Payable
A21: 18 राज्य बीमा | B21: 0 | C21: 37 नवीन पेंशन प्लान हेतु अंशदान 80CCD1 | D21: 64428
A22: 19 समूह बीमा प्रीमियम (GIS) | B22: =PAY!K24 -> 2400 | C22: 38 धारा 80 GG यदि वेतन में गृह भाडा भत्ता नहीं मिलता है या वर्ष मे कभी भी गृह भाड़ा भत्ता नहीं मिला है ।अधिकतम 60000 की छूट ,तीन शर्तों के साथ । | D22: 0 | E22: ='OLD TAX PLAN '!O63 -> 204
A23: ट्रायबल विभाग के शिक्षकों का संगठन " ट्रायबल वेल्फेयर टीचर्स एसोसिएशन म.प्र. " शिक्षकों के सहयोग के लिए निर्मित हमारी वेब साइट www.twtamp.in का अवलोकन अवश्य करें
A24: प्रदेशाध्यक्ष श्री डी के सिंगौर के मार्गदर्शन में श्री विजय उपाध्याय के सहयोग से प्रदेश महासचिव सुरेश यादव (9926809650) द्वारा निर्मित

Sheet OLD TAX PLAN 
A1: =PAY!A1 -> OFFICE Of HIGH SCHOOL BALIPUR
A2: vk;dj x.kuk izi= o"kZ 2020&2021¼dj fu/kkZj.k o"kZ 2021&2022½
A3: 1 | B3: कर्मचारी का नाम | D3: =PAY!B3 -> Laxman Devda | J3: पद | K3: =PAY!B4 -> Madhymik Shikshak | M3: PAN | N3: =PAY!L3 -> KLP00232K
A4: 2 | B4: आय वर्ष 2019-20 मे प्राप्त कुल वेतन ( कर गणना मे शामिल सभी भत्तों सहित ) | O4: =PAY!H24 -> 644304
A5: 3 | B5: गृह किराया धारा 10 (13-A) के अंतर्गत एवं धारा 10 (14) के अंतर्गत अन्य भत्ते जो कर मुक्त हैं | O5: =DEDUCTION!B4 -> 0
A6: 4 | B6: शेष (2-3) | O6: =O4-O5 -> 644304
A7: 5 | B7: (i) मनोरंजन भत्ता धारा 16 (ii) अंतर्गत (अधिकतम सीमा रु 5000) | L7: =DEDUCTION!B5 -> 0
B8: (ii) वृति कर 16 (iii) | L8: =DEDUCTION!B6 -> 2500
B9: (iii) स्टेन्डर्ड डीडक्शन (50000) केवल वेतनभोगी नागरीक के लिए | L9: =IF(O6<50000,O6,50000) -> 50000 | O9: =L9+L8+L7 -> 52500
A10: 6 | B10: 'ks"k ¼4&5½ | O10: =O6-O9 -> 591804
A11: 7 | B11: (अ) गृह संपत्ति से आय (1) स्वय के उपयोग मे -शून्य | J11: (2) किराया से आय | L11: =DEDUCTION!B7 -> 0
B12: (ब) घटाये | D12: किराये का 30 % | G12: गृह ऋण पर ब्याज | J12: गृहकर | L12: योग 7 (ब)
D13: =ROUND(L11*0.3,0) -> 0 | G13: =DEDUCTION!B10 -> 0 | J13: =DEDUCTION!B8 -> 0 | L13: =D13+G13+J13 -> 0
B14: शेष -/+(7(अ) एवं योग 7(ब) का) | O14: =L11-L13 -> 0
A15: 8 | B15: कुल शेष -/+ (6 एवं 7) | O15: =O14+O10 -> 591804
A16: 9 | B16: अन्य आय | O16: =DEDUCTION!D4+DEDUCTION!D5 -> 0
A17: 10 | B17: सकल आय योग (8+9) | O17: =O16+O15 -> 591804
A18: 11 | B18: घटाइए कटौतियाँ : - धारा US (80C, 80CCC,80CCD (1))
B19: (A) अधिकतम सीमा 1,50,000/- (धारा 80CCE) ,(धारा 80 CCD (2)) के अलावा
B20: (i) | C20: राज्य बीमा | G20: रु. | H20: =DEDUCTION!B21 -> 0 | I20: (x) | J20: सरकारी पेंशन योजना मे अंशदान ECPF | M20: रु. | N20: =DEDUCTION!D20 -> 0
B21: (ii) | C21: जीवन बीमा प्रीमियम | G21: रु. | H21: =DEDUCTION!B11 -> 0 | I21: (xi) | J21: नवीन पेंशन प्लान हेतु अंशदान 80CCD1 | M21: रु. | N21: =DEDUCTION!D21 -> 64428
B22: (iii) | C22: राष्ट्रीय बचत पत्र (NSC) | G22: रु. | H22: =DEDUCTION!B15 -> 24000 | I22: (xii) | J22: राष्ट्रीय बचत पत्र पर प्राप्त ब्याज | M22: रु. | N22: =DEDUCTION!B16 -> 0
B23: (iv) | C23: लोक भविष्य निधी (PPF) | G23: रु. | H23: =DEDUCTION!B17 -> 0 | I23: (xiii) | J23: शिक्षण शुल्क | M23: रु. | N23: =DEDUCTION!B13 -> 0
B24: (v) | C24: राष्ट्रीय बचत योजना (NSS) | G24: रु. | H24: =DEDUCTION!B18 -> 0 | I24: (xiv) | J24: म्यूचुअल फंड ELSS | M24: रु. | N24: =DEDUCTION!D16 -> 0
B25: (vi) | C25: सामान्य भविष्य निधी (GPF) | G25: रु. | H25: =DEDUCTION!B20 -> 0 | I25: (xv) | J25: स्थगित वार्षिकी (Defferred Annuty) | M25: रु. | N25: =DEDUCTION!D17 -> 0
B26: (vii) | C26: समूह बीमा प्रीमियम (GIS) | G26: रु. | H26: =DEDUCTION!B22 -> 2400 | I26: (xvi) | J26: पी.एल.आई. (PLI) | M26: रु. | N26: =DEDUCTION!B12 -> 0
B27: (viii) | C27: ULIP/वार्षिक प्लान | G27: रु. | H27: =DEDUCTION!B14 -> 0 | I27: (xvii) | J27: सुकन्या समृद्धि योजना मे जमा | M27: रु. | N27: =DEDUCTION!B19 -> 0
B28: (ix) | C28: गृह ऋण किश्त (मूलधन) | G28: रु. | H28: =DEDUCTION!B9 -> 0 | I28: (xviii) | J28: 80 C अंतर्गत अन्य निवेश | M28: रु. | N28: =DEDUCTION!D6 -> 0
B29: योग ( i से xviii ) | M29: रु. | N29: =N28+N27+N26+N25+N24+N23+N22+N21+N20+H28+H27+H26+H25+H24+H23+H22+H21+H20 -> 90828
B30: अधिकतम कटौति की राशी 150000/- लाख रुपए तक | O30: =IF(N29<150001,ROUND(N29,0),150000) -> 90828
B31: (B) घटाइये-धारा 80CCD (2) नियोक्ता द्वारा पेंशन अंशदान की राशि (अधिकतम वेतन का 10% ) पृथक से छूट | O31: =DEDUCTION!D7 -> 0
B32: (C) (B) धारा 80 CCD 1 (B) वेतन एवं नियोक्ता के अंशदान के अतिरिक्त 50000 तक का निवेश | O32: =IF(DEDUCTION!D8<50001,ROUND(DEDUCTION!D8,0),50000) -> 0
B33: योग 11 (A+B+C) | O33: =O32+O31+O30 -> 90828
A34: 12 | B34: अन्य कटौतियाँ
B35: 1- धारा 80 D मेडिक्लेम पालिसी (स्वय,जीवन साथी,बच्चों की 25000/-) आश्रित मातापिता का मेडिक्लेम 50000/- | O35: =DEDUCTION!D9 -> 0
B36: 2- धारा 80 DD दिव्यांग आश्रित के इलाज का खर्च का खर्च 40% से 80%तक दिव्यांग 75000/- 80% से अधिक दिव्यांग 125000/- | O36: =DEDUCTION!D10 -> 0
B37: 3- धारा 80DDB वीनिर्दिष्ट बीमारियों मे स्वयं या आश्रीत का इलाज का खर्च 60 से कम आयु वर्ग के लिए 40000/-, 60 से अधिक आयु वर्ग के लिए 100000/- | O37: =DEDUCTION!D11 -> 0
B38: 4- धारा 80 E उच्च शिक्षा ऋण के ब्याज को 8 वर्ष तक मुक्त किया गया है | O38: =DEDUCTION!D12 -> 0
B39: 5- धारा 80 G राष्ट्रिय,धर्मिक ,परमार्थ एवं सामाजिक कार्य हेतु दान राशी 50% से 100% कर मुक्त (आयकर विभाग की सूची अनुसार) | O39: =DEDUCTION!D13 -> 0
B40: 6-धारा 80 GG यदि वेतन में गृह भाडा भत्ता नहीं मिलता है या वर्ष मे कभी भी गृह भाड़ा भत्ता नहीं मिला है । | O40: =DEDUCTION!D22 -> 0
...

Sheet NEW PLAN 
A2: नवीन आयकर नियमों अनुसार 2020-2021 से वैकल्पिक कर गणना
A3: बिना छूट का लाभ लिए कर गणना
B5: स.क्र. | C5: सकल आय | G5: आयकर की दर | I5: =PAY!H24 -> 644304
B7: 1 | C7: 250000 तक | G7: NIL | I7: 0
B8: 2 | C8: 250001 से 300000 तक | G8: 0.05 | I8: =IF(I5<250001,0,IF(I5>300000,2500,((I5-250000)*0.05))) -> 2500
B9: 3 | C9: 300001 से 500000 तक | G9: 0.05 | I9: =IF(I5<300001,0,IF(I5>500000,10000,((I5-300000)*0.05))) -> 10000
B10: 4 | C10: 500001 से 750000 तक | G10: 0.1 | I10: =IF(I5<500001,0,IF(I5>750000,25000,((I5-500000)*0.1))) -> 14430.4
B11: 5 | C11: 750001 से 1000000 तक | G11: 0.15 | I11: =IF(I5<750001,0,IF(I5>1000000,37500,((I5-750000)*0.15))) -> 0
B12: 6 | C12: 1000001 से 1250000 तक | G12: 0.2 | I12: =IF(I5<1000001,0,IF(I5>1250000,50000,((I5-1000000)*0.2))) -> 0
B13: 7 | C13: 1250001 से 1500000 तक | G13: 0.25 | I13: =IF(I5<1250001,0,IF(I5>1500000,65000,((I5-1250000)*0.25))) -> 0
B14: 8 | C14: 1500001 से अधिक | G14: 0.3 | I14: =IF(I5<1500001,0,((I5-1500000)*0.3)) -> 0
C15: योग | I15: =I14+I13+I12+I11+I10+I9+I8+I7 -> 26930.4
A17: ट्रायबल विभाग के शिक्षकों का संगठन " ट्रायबल वेल्फेयर टीचर्स एसोसिएशन म.प्र. " शिक्षकों के सहयोग के लिए निर्मित हमारी वेब साइट www.twtamp.in का अवलोकन अवश्य करें
A18: प्रदेशाध्यक्ष श्री डी के सिंगौर के मार्गदर्शन में श्री विजय उपाध्याय के सहयोग से प्रदेश महासचिव सुरेश यादव (9926809650) द्वारा निर्मित

Sheet Sheet1
